backintime (1.2.1) unstable; urgency=low
  * Fix bug: TypeError in backintime.py if mount failed while running a snapshot (https://github.com/bit-team/backintime/issues/1005)
 -- Germar Reitze <germar.reitze@gmail.com>  Sun, 25 Aug 2019 18:10:34 +0200
